[0;33m--- idf_monitor on flash 115200 ---[0m
[0;33m--- Quit: Ctrl+] | Menu: Ctrl+T | Help: Ctrl+T followed by Ctrl+H ---[0m
Exception in thread Thread-2 (_run_outer):
Traceback (most recent call last):
  File "/home/metisa/.espressif/python_env/idf5.2_py3.10_env/lib/python3.10/site-packages/serial/serialposix.py", line 322, in open
    self.fd = os.open(self.portstr, os.O_RDWR | os.O_NOCTTY | os.O_NONBLOCK)
FileNotFoundError: [Errno 2] No such file or directory: 'flash'

During handling of the above exception, another exception occurred:

Traceback (most recent call last):
  File "/usr/lib/python3.10/threading.py", line 1016, in _bootstrap_inner
    self.run()
  File "/usr/lib/python3.10/threading.py", line 953, in run
    self._target(*self._args, **self._kwargs)
  File "/home/metisa/.espressif/python_env/idf5.2_py3.10_env/lib/python3.10/site-packages/esp_idf_monitor/base/stoppable_thread.py", line 47, in _run_outer
    self.run()
  File "/home/metisa/.espressif/python_env/idf5.2_py3.10_env/lib/python3.10/site-packages/esp_idf_monitor/base/serial_reader.py", line 53, in run
    self.serial.open()
  File "/home/metisa/.espressif/python_env/idf5.2_py3.10_env/lib/python3.10/site-packages/serial/serialposix.py", line 325, in open
    raise SerialException(msg.errno, "could not open port {}: {}".format(self._port, msg))
serial.serialutil.SerialException: [Errno 2] could not open port flash: [Errno 2] No such file or directory: 'flash'
[0m
